{"uuid": "adccb47e-e65b-4ad9-93a9-c19663c31f4e", "children": ["20024307-15a6-42bb-9060-dcbf3adcc6b3"], "befores": [{"name": "setup", "status": "broken", "statusDetails": {"message": "selenium.common.exceptions.WebDriverException: Message: An unknown server-side error occurred while processing the command. Original error: Could not find a connected Android device in 20073ms.\nStacktrace:\nUnknownError: An unknown server-side error occurred while processing the command. Original error: Could not find a connected Android device in 20073ms.\n    at getResponseForW3CError (/home/sohansagar/.nvm/versions/node/v14.17.3/lib/node_modules/appium/node_modules/appium-base-driver/lib/protocol/errors.js:804:9)\n    at asyncHandler (/home/sohansagar/.nvm/versions/node/v14.17.3/lib/node_modules/appium/node_modules/appium-base-driver/lib/protocol/protocol.js:380:37)\n", "trace": "  File \"/home/sohansagar/PycharmProjects/Appium/venv/lib/python3.8/site-packages/pluggy/_callers.py\", line 39, in _multicall\n    res = hook_impl.function(*args)\n  File \"/home/sohansagar/PycharmProjects/Appium/venv/lib/python3.8/site-packages/_pytest/fixtures.py\", line 1111, in pytest_fixture_setup\n    result = call_fixture_func(fixturefunc, request, kwargs)\n  File \"/home/sohansagar/PycharmProjects/Appium/venv/lib/python3.8/site-packages/_pytest/fixtures.py\", line 883, in call_fixture_func\n    fixture_result = next(generator)\n  File \"/home/sohansagar/PycharmProjects/Appium/Tests/conftest.py\", line 27, in setup\n    driver = webdriver.Remote(\"http://127.0.0.1:4723/wd/hub\", desired_caps)\n  File \"/home/sohansagar/PycharmProjects/Appium/venv/lib/python3.8/site-packages/appium/webdriver/webdriver.py\", line 274, in __init__\n    super().__init__(\n  File \"/home/sohansagar/PycharmProjects/Appium/venv/lib/python3.8/site-packages/selenium/webdriver/remote/webdriver.py\", line 266, in __init__\n    self.start_session(capabilities, browser_profile)\n  File \"/home/sohansagar/PycharmProjects/Appium/venv/lib/python3.8/site-packages/appium/webdriver/webdriver.py\", line 369, in start_session\n    response = self.execute(RemoteCommand.NEW_SESSION, parameters)\n  File \"/home/sohansagar/PycharmProjects/Appium/venv/lib/python3.8/site-packages/selenium/webdriver/remote/webdriver.py\", line 418, in execute\n    self.error_handler.check_response(response)\n  File \"/home/sohansagar/PycharmProjects/Appium/venv/lib/python3.8/site-packages/selenium/webdriver/remote/errorhandler.py\", line 243, in check_response\n    raise exception_class(message, screen, stacktrace)\n"}, "start": 1648481302856, "stop": 1648481323180}], "start": 1648481302856, "stop": 1648481323273}