{"uuid": "7b7aa1b5-bf40-4f6d-8188-416b15496894", "children": ["56009d9a-0b47-466c-a480-6bef64031c5c"], "befores": [{"name": "setup", "status": "broken", "statusDetails": {"message": "urllib3.exceptions.MaxRetryError: HTTPConnectionPool(host='127.0.0.1', port=4723): Max retries exceeded with url: /wd/hub/session (Caused by NewConnectionError('<urllib3.connection.HTTPConnection object at 0x7fe958463730>: Failed to establish a new connection: [Errno 111] Connection refused'))\n", "trace": "  File \"/home/sohansagar/PycharmProjects/Appium/venv/lib/python3.8/site-packages/pluggy/_callers.py\", line 39, in _multicall\n    res = hook_impl.function(*args)\n  File \"/home/sohansagar/PycharmProjects/Appium/venv/lib/python3.8/site-packages/_pytest/fixtures.py\", line 1111, in pytest_fixture_setup\n    result = call_fixture_func(fixturefunc, request, kwargs)\n  File \"/home/sohansagar/PycharmProjects/Appium/venv/lib/python3.8/site-packages/_pytest/fixtures.py\", line 883, in call_fixture_func\n    fixture_result = next(generator)\n  File \"/home/sohansagar/PycharmProjects/Appium/Tests/conftest.py\", line 27, in setup\n    driver = webdriver.Remote(\"http://127.0.0.1:4723/wd/hub\", desired_caps)\n  File \"/home/sohansagar/PycharmProjects/Appium/venv/lib/python3.8/site-packages/appium/webdriver/webdriver.py\", line 274, in __init__\n    super().__init__(\n  File \"/home/sohansagar/PycharmProjects/Appium/venv/lib/python3.8/site-packages/selenium/webdriver/remote/webdriver.py\", line 266, in __init__\n    self.start_session(capabilities, browser_profile)\n  File \"/home/sohansagar/PycharmProjects/Appium/venv/lib/python3.8/site-packages/appium/webdriver/webdriver.py\", line 369, in start_session\n    response = self.execute(RemoteCommand.NEW_SESSION, parameters)\n  File \"/home/sohansagar/PycharmProjects/Appium/venv/lib/python3.8/site-packages/selenium/webdriver/remote/webdriver.py\", line 416, in execute\n    response = self.command_executor.execute(driver_command, params)\n  File \"/home/sohansagar/PycharmProjects/Appium/venv/lib/python3.8/site-packages/selenium/webdriver/remote/remote_connection.py\", line 398, in execute\n    return self._request(command_info[0], url, body=data)\n  File \"/home/sohansagar/PycharmProjects/Appium/venv/lib/python3.8/site-packages/selenium/webdriver/remote/remote_connection.py\", line 420, in _request\n    resp = self._conn.request(method, url, body=body, headers=headers)\n  File \"/home/sohansagar/PycharmProjects/Appium/venv/lib/python3.8/site-packages/urllib3/request.py\", line 78, in request\n    return self.request_encode_body(\n  File \"/home/sohansagar/PycharmProjects/Appium/venv/lib/python3.8/site-packages/urllib3/request.py\", line 170, in request_encode_body\n    return self.urlopen(method, url, **extra_kw)\n  File \"/home/sohansagar/PycharmProjects/Appium/venv/lib/python3.8/site-packages/urllib3/poolmanager.py\", line 376, in urlopen\n    response = conn.urlopen(method, u.request_uri, **kw)\n  File \"/home/sohansagar/PycharmProjects/Appium/venv/lib/python3.8/site-packages/urllib3/connectionpool.py\", line 813, in urlopen\n    return self.urlopen(\n  File \"/home/sohansagar/PycharmProjects/Appium/venv/lib/python3.8/site-packages/urllib3/connectionpool.py\", line 813, in urlopen\n    return self.urlopen(\n  File \"/home/sohansagar/PycharmProjects/Appium/venv/lib/python3.8/site-packages/urllib3/connectionpool.py\", line 813, in urlopen\n    return self.urlopen(\n  File \"/home/sohansagar/PycharmProjects/Appium/venv/lib/python3.8/site-packages/urllib3/connectionpool.py\", line 785, in urlopen\n    retries = retries.increment(\n  File \"/home/sohansagar/PycharmProjects/Appium/venv/lib/python3.8/site-packages/urllib3/util/retry.py\", line 592, in increment\n    raise MaxRetryError(_pool, url, error or ResponseError(cause))\n"}, "start": 1648481222799, "stop": 1648481222802}], "start": 1648481222799, "stop": 1648481222980}